<?xml version="1.0" encoding="utf-8"?>
<!-- =================================================================================== -->
<!-- |    This document was autogenerated by xacro from robot.xacro                    | -->
<!-- |    EDITING THIS FILE BY HAND IS NOT RECOMMENDED                                 | -->
<!-- =================================================================================== -->
<robot name="mi4">
  <!-- dynamics inertial value -->
  <!-- trunk -->
  <!-- <xacro:property name="trunk_mass" value="5.660"/>
    <xacro:property name="trunk_com_x" value="0.012731"/>
    <xacro:property name="trunk_com_y" value="0.002186"/>
    <xacro:property name="trunk_com_z" value="0.000515"/>
    <xacro:property name="trunk_ixx" value="0.016839930"/>
    <xacro:property name="trunk_ixy" value="0.000083902"/>
    <xacro:property name="trunk_ixz" value="0.000597679"/>
    <xacro:property name="trunk_iyy" value="0.056579028"/>
    <xacro:property name="trunk_iyz" value="0.000025134"/>
    <xacro:property name="trunk_izz" value="0.064713601"/> -->
  <material name="black">
    <color rgba="0.0 0.0 0.0 1.0"/>
  </material>
  <material name="blue">
    <color rgba="0.0 0.0 0.8 1.0"/>
  </material>
  <material name="green">
    <color rgba="0.0 0.8 0.0 1.0"/>
  </material>
  <material name="grey">
    <color rgba="0.2 0.2 0.2 1.0"/>
  </material>
  <material name="silver">
    <color rgba="0.913725490196 0.913725490196 0.847058823529 1.0"/>
  </material>
  <material name="orange">
    <!-- <color rgba="1.0 0.423529411765 0.0392156862745 1.0"/> -->
    <color rgba="1.0 1.0 1.0 1.0"/>
  </material>
  <material name="brown">
    <color rgba="0.870588235294 0.811764705882 0.764705882353 1.0"/>
  </material>
  <material name="red">
    <color rgba="0.8 0.0 0.0 1.0"/>
  </material>
  <material name="white">
    <color rgba="1.0 1.0 1.0 1.0"/>
  </material>
  <!-- ros_control plugin -->
  <gazebo>
    <plugin filename="libgazebo_ros_control.so" name="gazebo_ros_control">
      <robotNamespace>/mi4_gazebo</robotNamespace>
      <robotSimType>gazebo_ros_control/DefaultRobotHWSim</robotSimType>
    </plugin>
  </gazebo>
  <!-- Show the trajectory of trunk center. -->
  <!-- <gazebo>
    <plugin filename="libLinkPlot3DPlugin.so" name="3dplotTrunk">
      <frequency>10</frequency>
      <plot>
        <link>base</link>
        <pose>0 0 0 0 0 0</pose>
        <material>Gazebo/Yellow</material>
      </plot>
    </plugin>
  </gazebo> -->
  <!-- Show the trajectory of foot. You can add another trajectory about another foot. -->
  <!-- <gazebo>
    <plugin filename="libLinkPlot3DPlugin.so" name="3dplot">
      <frequency>1000</frequency>
      <plot>
        <link>FR_calf</link>
        <pose>0 0 -0.2 0 0 0</pose>
        <material>Gazebo/Yellow</material>
      </plot>
    </plugin>
  </gazebo> -->
  <gazebo>
    <plugin filename="libgazebo_ros_force.so" name="gazebo_ros_force">
      <bodyName>trunk</bodyName>
      <topicName>/apply_force/trunk</topicName>
    </plugin>
  </gazebo>
  <gazebo reference="imu_link">
    <gravity>true</gravity>
    <sensor name="imu_sensor" type="imu">
      <always_on>true</always_on>
      <update_rate>1000</update_rate>
      <visualize>true</visualize>
      <topic>__default_topic__</topic>
      <plugin filename="libgazebo_ros_imu_sensor.so" name="imu_plugin">
        <topicName>trunk_imu</topicName>
        <bodyName>imu_link</bodyName>
        <updateRateHZ>1000.0</updateRateHZ>
        <gaussianNoise>0.0</gaussianNoise>
        <xyzOffset>0 0 0</xyzOffset>
        <rpyOffset>0 0 0</rpyOffset>
        <frameName>imu_link</frameName>
      </plugin>
      <pose>0 0 0 0 0 0</pose>
    </sensor>
  </gazebo>
  <!-- Foot contacts. -->
  <!-- <gazebo reference="FR_calf">
    <sensor name="FR_foot_contact" type="contact">
      <update_rate>100</update_rate>
      <plugin filename="libunitreeFootContactPlugin.so" name="contactPlugin"/>
      <contact>
        <collision>FR_calf_fixed_joint_lump__FR_foot_collision_1</collision>
      </contact>
    </sensor>
  </gazebo>
  <gazebo reference="FL_calf">
    <sensor name="FL_foot_contact" type="contact">
      <update_rate>100</update_rate>
      <plugin filename="libunitreeFootContactPlugin.so" name="contactPlugin"/>
      <contact>
        <collision>FL_calf_fixed_joint_lump__FL_foot_collision_1</collision>
      </contact>
    </sensor>
  </gazebo>
  <gazebo reference="RR_calf">
    <sensor name="RR_foot_contact" type="contact">
      <update_rate>100</update_rate>
      <plugin filename="libunitreeFootContactPlugin.so" name="contactPlugin"/>
      <contact>
        <collision>RR_calf_fixed_joint_lump__RR_foot_collision_1</collision>
      </contact>
    </sensor>
  </gazebo>
  <gazebo reference="RL_calf">
    <sensor name="RL_foot_contact" type="contact">
      <update_rate>100</update_rate>
      <plugin filename="libunitreeFootContactPlugin.so" name="contactPlugin"/>
      <contact>
        <collision>RL_calf_fixed_joint_lump__RL_foot_collision_1</collision>
      </contact>
    </sensor>
  </gazebo> -->
  <!-- Visualization of Foot contacts. -->
  <!-- <gazebo reference="FR_foot">
    <visual>
      <plugin filename="libunitreeDrawForcePlugin.so" name="drawForcePlugin">
        <topicName>FR_foot_contact</topicName>
      </plugin>
    </visual>
  </gazebo>
  <gazebo reference="FL_foot">
    <visual>
      <plugin filename="libunitreeDrawForcePlugin.so" name="drawForcePlugin">
        <topicName>FL_foot_contact</topicName>
      </plugin>
    </visual>
  </gazebo>
  <gazebo reference="RR_foot">
    <visual>
      <plugin filename="libunitreeDrawForcePlugin.so" name="drawForcePlugin">
        <topicName>RR_foot_contact</topicName>
      </plugin>
    </visual>
  </gazebo>
  <gazebo reference="RL_foot">
    <visual>
      <plugin filename="libunitreeDrawForcePlugin.so" name="drawForcePlugin">
        <topicName>RL_foot_contact</topicName>
      </plugin>
    </visual>
  </gazebo> -->
  <gazebo reference="base">
    <material>Gazebo/Green</material>
    <turnGravityOff>false</turnGravityOff>
  </gazebo>
  <gazebo reference="trunk">
    <mu1>0.2</mu1>
    <mu2>0.2</mu2>
    <kp value="1000000.0"/>
    <kd value="1.0"/>
  </gazebo>
  <gazebo reference="stick_link">
    <mu1>0.2</mu1>
    <mu2>0.2</mu2>
    <material>Gazebo/White</material>
  </gazebo>
  <gazebo reference="imu_link">
    <mu1>0.2</mu1>
    <mu2>0.2</mu2>
    <material>Gazebo/Red</material>
  </gazebo>
  <!-- FL leg -->
  <gazebo reference="FL_hip">
    <mu1>0.2</mu1>
    <mu2>0.2</mu2>
    <material>Gazebo/DarkGrey</material>
  </gazebo>
  <gazebo reference="FL_thigh">
    <mu1>0.2</mu1>
    <mu2>0.2</mu2>
    <self_collide>1</self_collide>
    <material>Gazebo/DarkGrey</material>
    <kp value="1000000.0"/>
    <kd value="1.0"/>
  </gazebo>
  <gazebo reference="FL_calf">
    <mu1>0.2</mu1>
    <mu2>0.2</mu2>
    <self_collide>1</self_collide>
  </gazebo>
  <gazebo reference="FL_foot">
    <mu1>0.6</mu1>
    <mu2>0.6</mu2>
    <self_collide>1</self_collide>
    <material>Gazebo/DarkGrey</material>
    <kp value="1000000.0"/>
    <kd value="1.0"/>
  </gazebo>
  <!-- FR leg -->
  <gazebo reference="FR_hip">
    <mu1>0.2</mu1>
    <mu2>0.2</mu2>
    <material>Gazebo/DarkGrey</material>
  </gazebo>
  <gazebo reference="FR_thigh">
    <mu1>0.2</mu1>
    <mu2>0.2</mu2>
    <self_collide>1</self_collide>
    <material>Gazebo/DarkGrey</material>
    <kp value="1000000.0"/>
    <kd value="1.0"/>
  </gazebo>
  <gazebo reference="FR_calf">
    <mu1>0.2</mu1>
    <mu2>0.2</mu2>
    <self_collide>1</self_collide>
  </gazebo>
  <gazebo reference="FR_foot">
    <mu1>0.6</mu1>
    <mu2>0.6</mu2>
    <self_collide>1</self_collide>
    <material>Gazebo/DarkGrey</material>
    <kp value="1000000.0"/>
    <kd value="1.0"/>
  </gazebo>
  <!-- RL leg -->
  <gazebo reference="RL_hip">
    <mu1>0.2</mu1>
    <mu2>0.2</mu2>
    <material>Gazebo/DarkGrey</material>
  </gazebo>
  <gazebo reference="RL_thigh">
    <mu1>0.2</mu1>
    <mu2>0.2</mu2>
    <self_collide>1</self_collide>
    <material>Gazebo/DarkGrey</material>
    <kp value="1000000.0"/>
    <kd value="1.0"/>
  </gazebo>
  <gazebo reference="RL_calf">
    <mu1>0.2</mu1>
    <mu2>0.2</mu2>
    <self_collide>1</self_collide>
  </gazebo>
  <gazebo reference="RL_foot">
    <mu1>0.6</mu1>
    <mu2>0.6</mu2>
    <self_collide>1</self_collide>
    <material>Gazebo/DarkGrey</material>
    <kp value="1000000.0"/>
    <kd value="1.0"/>
  </gazebo>
  <!-- RR leg -->
  <gazebo reference="RR_hip">
    <mu1>0.2</mu1>
    <mu2>0.2</mu2>
    <material>Gazebo/DarkGrey</material>
  </gazebo>
  <gazebo reference="RR_thigh">
    <mu1>0.2</mu1>
    <mu2>0.2</mu2>
    <self_collide>1</self_collide>
    <material>Gazebo/DarkGrey</material>
    <kp value="1000000.0"/>
    <kd value="1.0"/>
  </gazebo>
  <gazebo reference="RR_calf">
    <mu1>0.2</mu1>
    <mu2>0.2</mu2>
    <self_collide>1</self_collide>
  </gazebo>
  <gazebo reference="RR_foot">
    <mu1>0.6</mu1>
    <mu2>0.6</mu2>
    <self_collide>1</self_collide>
    <material>Gazebo/DarkGrey</material>
    <kp value="1000000.0"/>
    <kd value="1.0"/>
  </gazebo>
  <!-- <xacro:include filename="$(find mi_gazebo)/launch/stairs.urdf.xacro"/> -->
  <!-- <xacro:stairs stairs="15" xpos="0" ypos="0" zpos="0" /> -->
  <!-- Debug mode will hung up the robot, use "true" or "false" to switch it. -->
  <!-- <xacro:if value="$(arg DEBUG)">
        <link name="world"/>
        <joint name="base_static_joint" type="fixed">
            <origin rpy="0 0 0" xyz="0 0 0"/>
            <parent link="world"/>
            <child link="base"/>
        </joint>
    </xacro:if>  -->

  <link name="base">
    <visual>
      <origin rpy="0 0 0" xyz="0 0 0"/>
      <geometry>
        <box size="0.001 0.001 0.001"/>
      </geometry>
    </visual>
    <inertial>
      <mass value="0.001"/>
      <origin rpy="0 0 0" xyz="0 0 0"/>
      <inertia ixx="0.0001" ixy="0" ixz="0" iyy="0.0001" iyz="0" izz="0.0001"/>
    </inertial>
  </link>

  <joint name="floating_base" type="fixed">
    <origin rpy="0 0 0" xyz="0 0 0.15"/>
    <parent link="base"/>
    <child link="trunk"/>
  </joint>

  <link name="trunk">
    <visual>
      <origin rpy="0 0 0" xyz="0 0 0"/>
      <geometry>
        <mesh filename="../meshes/trunk.STL" scale="1 1 1"/>
      </geometry>
      <material name="silver"/>
    </visual>
    <collision>
        <origin
                xyz="0 0 0.0"
                rpy="0 0 0" />
        <geometry>
            <box size="0.5 0.25 0.15" />
        </geometry>
        <!-- <geometry>
          <mesh filename="../meshes/trunk.STL" scale="1 1 1"/>
        </geometry> -->
    </collision>
    <inertial>
      <origin rpy="0 0 0" xyz="0.0071857 -0.0066153 0.0048874"/>
      <mass value="30.507"/>
      <inertia
        ixx="0.16499"
        ixy="4.3311E-06"
        ixz="0.00067599"
        iyy="0.38339"
        iyz="-5.15E-05"
        izz="0.46879" />
    </inertial>
  </link>

  <joint name="imu_joint" type="fixed">
    <parent link="trunk"/>
    <child link="imu_link"/>
    <origin rpy="0 0 0" xyz="0 0 0"/>
  </joint>

  <link name="imu_link">
    <inertial>
      <mass value="0.001"/>
      <origin rpy="0 0 0" xyz="0 0 0"/>
      <inertia ixx="0.0001" ixy="0" ixz="0" iyy="0.0001" iyz="0" izz="0.0001"/>
    </inertial>
    <visual>
      <origin rpy="0 0 0" xyz="0 0 0"/>
      <geometry>
        <box size="0.001 0.001 0.001"/>
      </geometry>
      <material name="red"/>
    </visual>
    <collision>
      <origin rpy="0 0 0" xyz="0 0 0"/>
      <geometry>
        <box size=".001 .001 .001"/>
      </geometry>
    </collision>
  </link>


  <!-- FL -->
  <joint name="FL_hip_joint" type="revolute">
    <origin rpy="0 0 0" xyz="0.2555 0.072 0"/>
    <parent link="trunk"/>
    <child link="FL_hip"/>
    <axis xyz="1 0 0"/>
    <dynamics damping="0.01" friction="0.2"/>
    <limit lower="-0.698" upper="0.698" effort="360" velocity="12" />  
  </joint>

  <link name="FL_hip">
    <visual>
      <origin rpy="0 0 0" xyz="0 0 0"/>
      <geometry>
        <mesh filename="../meshes/FL_hip.STL" scale="1 1 1"/>
      </geometry>
      <material name="orange"/>
    </visual>
    <collision>
        <origin
                xyz="0.07 0 0"
                rpy="1.57 0 0" />
        <geometry>
            <!-- <cylinder radius="0.06" length="0.04" /> -->
            <cylinder radius="0.065" length="0.065" />
        </geometry>
        <!-- <origin rpy="0 0 0" xyz="0 0 0"/>
        <geometry>
          <mesh filename="../meshes/FL_hip.STL" scale="1 1 1"/>
        </geometry> -->
    </collision>
    <inertial>
      <origin rpy="0 0 0" xyz="0.053504 0.012415 -1.0281E-08"/>
      <mass value="0.7403"/>
      <inertia
        ixx="0.0012546"
        ixy="0.0002197"
        ixz="-7.3186E-08"
        iyy="0.0019096"
        iyz="-2.0638E-08"
        izz="0.0014821" />
    </inertial>
  </link>

  <joint name="FL_thigh_joint" type="revolute">
    <origin rpy="0 0 0" xyz="0.0875 0.0395 0"/>
    <parent link="FL_hip"/>
    <child link="FL_thigh"/>
    <axis xyz="0 1 0"/>
    <dynamics damping="0.01" friction="0.2"/>
    <limit lower="-2.840" upper="2.840" effort="360" velocity="12" />
  </joint>

  <link name="FL_thigh">
    <visual>
      <origin rpy="0 0 0" xyz="0 0 0"/>
      <geometry>
        <mesh filename="../meshes/FL_thigh.STL" scale="1 1 1"/>
      </geometry>
      <material name="orange"/>
    </visual>
    <collision>
        <origin
                xyz="0 0.13 -0.1"
                rpy="0 1.57 0" />
        <geometry>
            <!-- <box size="0.25 0.03 0.03" /> -->
            <box size="0.35 0.04 0.04" />
        </geometry>
        <!-- <origin rpy="0 0 0" xyz="0 0 0"/>
        <geometry>
          <mesh filename="../meshes/FL_thigh.STL" scale="1 1 1"/>
        </geometry> -->
    </collision>
    <inertial>
      <origin rpy="0 0 0" xyz="-0.010665 0.10447 -0.098926"/>
      <mass value="2.525"/>
      <inertia
        ixx="0.025442"
        ixy="2.2395E-06"
        ixz="0.00087476"
        iyy="0.027265"
        iyz="0.00015571"
        izz="0.0023975" />
    </inertial>
  </link>

  <joint name="FL_calf_joint" type="revolute">
    <origin rpy="0 0 0" xyz="0 0.1218 -0.35"/>
    <parent link="FL_thigh"/>
    <child link="FL_calf"/>
    <axis xyz="0 1 0"/>
    <dynamics damping="0.01" friction="0.2"/>
    <limit lower="-2.76634" upper="-0.68067" effort="360" velocity="12" />
  </joint>

  <link name="FL_calf">
    <visual>
      <origin rpy="0 0 0" xyz="0 0 0"/>
      <geometry>
        <mesh filename="../meshes/FL_calf.STL" scale="1 1 1"/>
      </geometry>
      <material name="orange"/>
    </visual>
    <collision>
        <!-- <origin
                xyz="0 0 -0.1"
                rpy="0 -0.18 0" />
        <geometry>
            <box size="0.02 0.03 0.2" />
        </geometry> -->
        <origin rpy="0 0 0" xyz="0 0 0"/>
        <geometry>
          <mesh filename="../meshes/FL_calf.STL" scale="1 1 1"/>
        </geometry>
    </collision>
    <inertial>
      <origin xyz="0.020605 2.0212E-05 -0.17304" rpy="0 0 0" />
      <mass value="0.64862"/>
      <inertia
        ixx="0.0096705"
        ixy="-1.0312E-07"
        ixz="-0.00070677"
        iyy="0.0098542"
        iyz="2.2788E-06"
        izz="0.00031766" />
    </inertial>
  </link>

  <joint name="FL_foot_fixed" type="fixed">
    <origin rpy="0 0 0" xyz="0 0 -0.35"/>
    <parent link="FL_calf"/>
    <child link="FL_foot"/>
  </joint>

  <link name="FL_foot">
    <visual>
      <origin rpy="0 0 0" xyz="0 0 0"/>
      <geometry>
        <mesh filename="../meshes/FL_foot.STL" scale="1 1 1"/>
      </geometry>
      <material name="orange"/>
    </visual>
    <collision>
      <origin rpy="0 0 0" xyz="0 0 0"/>
      <geometry>
        <mesh filename="../meshes/FL_foot.STL" scale="1 1 1"/>
      </geometry>
    </collision>
    <inertial>
      <origin xyz="-0.0069944 -5.1023E-08 -0.0064736" rpy="0 0 0" />
      <mass value="0.17599"/>
      <inertia
        ixx="0.00011036"
        ixy="7.0563E-10"
        ixz="-3.5069E-05"
        iyy="9.5157E-05"
        iyz="-7.843E-10"
        izz="0.00010548" />
      </inertial>
  </link>

  <transmission name="FL_hip_tran">
    <type>transmission_interface/SimpleTransmission</type>
    <joint name="FL_hip_joint">
      <hardwareInterface>hardware_interface/EffortJointInterface</hardwareInterface>
    </joint>
    <actuator name="FL_hip_motor">
      <hardwareInterface>hardware_interface/EffortJointInterface</hardwareInterface>
      <mechanicalReduction>1</mechanicalReduction>
    </actuator>
  </transmission>
  <transmission name="FL_thigh_tran">
    <type>transmission_interface/SimpleTransmission</type>
    <joint name="FL_thigh_joint">
      <hardwareInterface>hardware_interface/EffortJointInterface</hardwareInterface>
    </joint>
    <actuator name="FL_thigh_motor">
      <hardwareInterface>hardware_interface/EffortJointInterface</hardwareInterface>
      <mechanicalReduction>1</mechanicalReduction>
    </actuator>
  </transmission>
  <transmission name="FL_calf_tran">
    <type>transmission_interface/SimpleTransmission</type>
    <joint name="FL_calf_joint">
      <hardwareInterface>hardware_interface/EffortJointInterface</hardwareInterface>
    </joint>
    <actuator name="FL_calf_motor">
      <hardwareInterface>hardware_interface/EffortJointInterface</hardwareInterface>
      <mechanicalReduction>1</mechanicalReduction>
    </actuator>
  </transmission>

  <!-- FR -->
  <joint name="FR_hip_joint" type="revolute">
    <origin rpy="0 0 0" xyz="0.2556 -0.072 0"/>
    <parent link="trunk"/>
    <child link="FR_hip"/>
    <axis xyz="1 0 0"/>
    <dynamics damping="0.01" friction="0.2"/>
    <limit lower="-0.698" upper="0.698" effort="360" velocity="12" />
  </joint>

  <link name="FR_hip">
    <visual>
      <origin rpy="3.14159265359 0 0" xyz="0 0 0"/>
      <geometry>
        <mesh filename="../meshes/FR_hip.STL" scale="1 1 1"/>
      </geometry>
      <material name="orange"/>
    </visual>
    <collision>
        <!-- <origin
                xyz="0.07 0 0"
                rpy="1.57 0 0" />
        <geometry>
            <cylinder radius="0.06" length="0.04" />
        </geometry> -->
        <origin rpy="0 0 0" xyz="0 0 0"/>
        <geometry>
          <mesh filename="../meshes/FR_hip.STL" scale="1 1 1"/>
        </geometry>
    </collision>
    <inertial>
      <origin rpy="0 0 0" xyz="0.07174680 -0.00884881 0.00061318"/>
      <mass value="1.69792394"/>
      <inertia
        ixx="0.00070656"
        ixy="0.00007177"
        ixz="-0.00000421"
        iyy="0.00151552"
        iyz="-0.00000420"
        izz="0.00112887" />    
      </inertial>
  </link>
  
  <joint name="FR_thigh_joint" type="revolute">
    <origin rpy="0 0 0" xyz="0.0758 -0.03 0"/>
    <parent link="FR_hip"/>
    <child link="FR_thigh"/>
    <axis xyz="0 1 0"/>
    <dynamics damping="0.01" friction="0.2"/>
    <limit lower="-2.840" upper="2.840" effort="360" velocity="12" />
  </joint>

  <link name="FR_thigh">
    <visual>
      <origin rpy="0 0 0" xyz="0 0 0"/>
      <geometry>
        <mesh filename="../meshes/FR_thigh.STL" scale="1 1 1"/>
      </geometry>
      <material name="orange"/>
    </visual>
    <collision>
        <!-- <origin
                xyz="0 -0.13 -0.1"
                rpy="0 1.57 0" />
        <geometry>
            <box size="0.25 0.03 0.03" />
        </geometry> -->
        <geometry>
          <mesh filename="../meshes/FR_thigh.STL" scale="1 1 1"/>
        </geometry>
    </collision>
    <inertial>
      <origin rpy="0 0 0" xyz="-0.00586536 -0.10017101 -0.05380478"/>
      <mass value="4.60487764"/>
      <inertia
        ixx="0.06414647"
        ixy="-0.00102927"
        ixz="-0.00337200"
        iyy="0.06137458"
        iyz="-0.00957586"
        izz="0.01303443" />
    </inertial>
  </link>

  <joint name="FR_calf_joint" type="revolute">
    <origin rpy="0 0 0" xyz="0 -0.1398 -0.35"/>
    <parent link="FR_thigh"/>
    <child link="FR_calf"/>
    <axis xyz="0 1 0"/>
    <dynamics damping="0.01" friction="0.2"/>
    <limit lower="-2.76634" upper="-0.68067" effort="360" velocity="12" />
  </joint>
  <link name="FR_calf">
    <visual>
      <origin rpy="0 0 0" xyz="0 0 0"/>
      <geometry>
        <mesh filename="../meshes/FR_calf.STL" scale="1 1 1"/>
      </geometry>
      <material name="orange"/>
    </visual>
    <collision>
        <!-- <origin
                xyz="0 0 -0.1"
                rpy="0 -0.18 0" />
        <geometry>
            <box size="0.02 0.03 0.2" />
        </geometry> -->
        <origin rpy="0 0 0" xyz="0 0 0"/>
        <geometry>
          <mesh filename="../meshes/FR_calf.STL" scale="1 1 1"/>
        </geometry>
    </collision>
    <inertial>
      <origin rpy="0 0 0" xyz="0.019991 -6.7686E-09 -0.16457"/>
      <mass value="0.55861"/>
      <inertia
        ixx="0.0082184"
        ixy="4.9776E-11"
        ixz="0.00057642"
        iyy="0.0083728"
        iyz="3.8716E-10"
        izz="0.00026294" />
      </inertial>
  </link>

  <joint name="FR_foot_fixed" type="fixed">
    <origin rpy="0 0 0" xyz="0 0 -0.35"/>
    <parent link="FR_calf"/>
    <child link="FR_foot"/>
  </joint>

  <link name="FR_foot">
    <visual>
      <origin rpy="0 0 0" xyz="0 0 0"/>
      <geometry>
        <mesh filename="../meshes/FR_foot.STL" scale="1 1 1"/>
      </geometry>
      <material name="orange"/>
    </visual>
    <collision>
      <origin rpy="0 0 0" xyz="0 0 0"/>
      <geometry>
        <mesh filename="../meshes/FR_foot.STL" scale="1 1 1"/>
      </geometry>
    </collision>
    <inertial>
      <mass value="0.10687"/>
      <inertia
        ixx="0.00006750"
        ixy="0.00000000"
        ixz="0.00001553"
        iyy="0.00005963"
        iyz="0.00000000"
        izz="0.00006533" />
    </inertial>
  </link>

  <transmission name="FR_hip_tran">
    <type>transmission_interface/SimpleTransmission</type>
    <joint name="FR_hip_joint">
      <hardwareInterface>hardware_interface/EffortJointInterface</hardwareInterface>
    </joint>
    <actuator name="FR_hip_motor">
      <hardwareInterface>hardware_interface/EffortJointInterface</hardwareInterface>
      <mechanicalReduction>1</mechanicalReduction>
    </actuator>
  </transmission>
  <transmission name="FR_thigh_tran">
    <type>transmission_interface/SimpleTransmission</type>
    <joint name="FR_thigh_joint">
      <hardwareInterface>hardware_interface/EffortJointInterface</hardwareInterface>
    </joint>
    <actuator name="FR_thigh_motor">
      <hardwareInterface>hardware_interface/EffortJointInterface</hardwareInterface>
      <mechanicalReduction>1</mechanicalReduction>
    </actuator>
  </transmission>
  <transmission name="FR_calf_tran">
    <type>transmission_interface/SimpleTransmission</type>
    <joint name="FR_calf_joint">
      <hardwareInterface>hardware_interface/EffortJointInterface</hardwareInterface>
    </joint>
    <actuator name="FR_calf_motor">
      <hardwareInterface>hardware_interface/EffortJointInterface</hardwareInterface>
      <mechanicalReduction>1</mechanicalReduction>
    </actuator>
  </transmission>

  <!-- RL -->
  <joint name="RL_hip_joint" type="revolute">
    <origin rpy="0 0 0" xyz="-0.2555 0.072 0"/>
    <parent link="trunk"/>
    <child link="RL_hip"/>
    <axis xyz="1 0 0"/>
    <dynamics damping="0.01" friction="0.2"/>
    <limit lower="-0.698" upper="0.698" effort="360" velocity="12" />
  </joint>

  <link name="RL_hip">
    <visual>
      <origin rpy="0 0 0" xyz="0 0 0"/>
      <geometry>
        <mesh filename="../meshes/RL_hip.STL" scale="1 1 1"/>
      </geometry>
      <material name="orange"/>
    </visual>
    <collision>
        <!-- <origin
                xyz="-0.07 0 0"
                rpy="1.57 0 0" />
        <geometry>
            <cylinder radius="0.06" length="0.04" />
        </geometry> -->
        <origin rpy="0 0 0" xyz="0 0 0"/>
        <geometry>
          <mesh filename="../meshes/RL_hip.STL" scale="1 1 1"/>
        </geometry>
    </collision>
    <inertial>
      <origin rpy="0 0 0" xyz="-0.053504 0.012415 1.0289E-08"/>
      <mass value="0.7403"/>
      <inertia
        ixx="0.0012546"
        ixy="-0.0002197"
        ixz="-7.3186E-08"
        iyy="0.0019096"
        iyz="2.0637E-08"
        izz="0.0014821" />
    </inertial>
  </link>

  <joint name="RL_thigh_joint" type="revolute">
    <origin rpy="0 0 0" xyz="-0.0875 0.0395 0"/>
    <parent link="RL_hip"/>
    <child link="RL_thigh"/>
    <axis xyz="0 1 0"/>
    <dynamics damping="0.01" friction="0.2"/>
    <limit lower="-2.840" upper="2.840" effort="360" velocity="12" />
  </joint>
  <link name="RL_thigh">
    <visual>
      <origin rpy="0 0 0" xyz="0 0 0"/>
      <geometry>
        <mesh filename="../meshes/RL_thigh.STL" scale="1 1 1"/>
      </geometry>
      <material name="orange"/>
    </visual>
    <collision>
        <!-- <origin
                xyz="0 0.13 -0.1"
                rpy="0 1.57 0" />
        <geometry>
            <box size="0.25 0.03 0.03" />
        </geometry> -->
        <origin rpy="0 0 0" xyz="0 0 0"/>
        <geometry>
          <mesh filename="../meshes/RL_thigh.STL" scale="1 1 1"/>
        </geometry>
    </collision>
    <inertial>
      <origin rpy="0 0 0" xyz="-0.010665 0.10447 -0.098926"/>
      <mass value="2.525"/>
      <inertia
        ixx="0.025442"
        ixy="2.2397E-06"
        ixz="0.00087476"
        iyy="0.027265"
        iyz="0.00015571"
        izz="0.0023975" />
    </inertial>
  </link>

  <joint name="RL_calf_joint" type="revolute">
    <origin rpy="0 0 0" xyz="0 0.1218 -0.35"/>
    <parent link="RL_thigh"/>
    <child link="RL_calf"/>
    <axis xyz="0 1 0"/>
    <dynamics damping="0.01" friction="0.2"/>
    <limit lower="-2.76634" upper="-0.68067" effort="360" velocity="12" />
  </joint>

  <link name="RL_calf">
    <visual>
      <origin rpy="0 0 0" xyz="0 0 0"/>
      <geometry>
        <mesh filename="../meshes/RL_calf.STL" scale="1 1 1"/>
      </geometry>
      <material name="orange"/>
    </visual>
    <collision>
        <!-- <origin
                xyz="0 0 -0.1"
                rpy="0 -0.18 0" />
        <geometry>
            <box size="0.02 0.03 0.2" />
        </geometry> -->
        <origin rpy="0 0 0" xyz="0 0 0"/>
        <geometry>
          <mesh filename="../meshes/RL_calf.STL" scale="1 1 1"/>
        </geometry>
    </collision>
    <inertial>
      <origin rpy="0 0 0" xyz="0.020605 2.0212E-05 -0.17304"/>
      <mass value="0.64862"/>
      <inertia
        ixx="0.0096705"
        ixy="-1.0312E-07"
        ixz="-0.00070677"
        iyy="0.0098542"
        iyz="2.2788E-06"
        izz="0.00031766" />
    </inertial>
  </link>

  <joint name="RL_foot_fixed" type="fixed">
    <origin rpy="0 0 0" xyz="0 0 -0.35"/>
    <parent link="RL_calf"/>
    <child link="RL_foot"/>
  </joint>

  <link name="RL_foot">
    <visual>
      <origin rpy="0 0 0" xyz="0 0 0"/>
      <geometry>
        <mesh filename="../meshes/RL_foot.STL" scale="1 1 1"/>
      </geometry>
      <material name="orange"/>
    </visual>
    <collision>
      <origin rpy="0 0 0" xyz="0 0 0"/>
      <geometry>
        <mesh filename="../meshes/RL_foot.STL" scale="1 1 1"/>
      </geometry>
    </collision>
    <inertial>
      <origin
        xyz="-0.0069944 -5.1023E-08 -0.0064736"
        rpy="0 0 0" />
      <mass value="0.17599"/>
      <inertia
        ixx="0.00011036"
        ixy="7.0563E-10"
        ixz="-3.5069E-05"
        iyy="9.5157E-05"
        iyz="-7.843E-10"
        izz="0.00010548" />
    </inertial>
  </link>

  <transmission name="RL_hip_tran">
    <type>transmission_interface/SimpleTransmission</type>
    <joint name="RL_hip_joint">
      <hardwareInterface>hardware_interface/EffortJointInterface</hardwareInterface>
    </joint>
    <actuator name="RL_hip_motor">
      <hardwareInterface>hardware_interface/EffortJointInterface</hardwareInterface>
      <mechanicalReduction>1</mechanicalReduction>
    </actuator>
  </transmission>
  <transmission name="RL_thigh_tran">
    <type>transmission_interface/SimpleTransmission</type>
    <joint name="RL_thigh_joint">
      <hardwareInterface>hardware_interface/EffortJointInterface</hardwareInterface>
    </joint>
    <actuator name="RL_thigh_motor">
      <hardwareInterface>hardware_interface/EffortJointInterface</hardwareInterface>
      <mechanicalReduction>1</mechanicalReduction>
    </actuator>
  </transmission>
  <transmission name="RL_calf_tran">
    <type>transmission_interface/SimpleTransmission</type>
    <joint name="RL_calf_joint">
      <hardwareInterface>hardware_interface/EffortJointInterface</hardwareInterface>
    </joint>
    <actuator name="RL_calf_motor">
      <hardwareInterface>hardware_interface/EffortJointInterface</hardwareInterface>
      <mechanicalReduction>1</mechanicalReduction>
    </actuator>
  </transmission>

  <!-- RR -->
  <joint name="RR_hip_joint" type="revolute">
    <origin rpy="0 0 0" xyz="-0.2555 -0.072 0"/>
    <parent link="trunk"/>
    <child link="RR_hip"/>
    <axis xyz="1 0 0"/>
    <dynamics damping="0.01" friction="0.2"/>
    <limit lower="-0.698" upper="0.698" effort="360" velocity="12" />
  </joint>

  <link name="RR_hip">
    <visual>
      <origin rpy="0 0 0" xyz="0 0 0"/>
      <geometry>
        <mesh filename="../meshes/RR_hip.STL" scale="1 1 1"/>
      </geometry>
      <material name="orange"/>
    </visual>
    <collision>
        <!-- <origin
                xyz="-0.07 0 0"
                rpy="1.57 0 0" />
        <geometry>
            <cylinder radius="0.06" length="0.04" />
        </geometry> -->
        <origin rpy="0 0 0" xyz="0 0 0"/>
        <geometry>
          <mesh filename="../meshes/RR_hip.STL" scale="1 1 1"/>
        </geometry>
    </collision>
    <inertial>
      <origin rpy="0 0 0" xyz="-0.053504 -0.012415 -1.0288E-08"/>
      <mass value="0.7403"/>
      <inertia
        ixx="0.0012546"
        ixy="0.0002197"
        ixz="7.3186E-08"
        iyy="0.0019096"
        iyz="2.0637E-08"
        izz="0.0014821" />
    </inertial>
  </link>

  <joint name="RR_thigh_joint" type="revolute">
    <origin rpy="0 0 0" xyz="-0.0875 -0.0395 0"/>
    <parent link="RR_hip"/>
    <child link="RR_thigh"/>
    <axis xyz="0 1 0"/>
    <dynamics damping="0.01" friction="0.2"/>
    <limit lower="-2.840" upper="2.840" effort="360" velocity="12" />
  </joint>

  <link name="RR_thigh">
    <visual>
      <origin rpy="0 0 0" xyz="0 0 0"/>
      <geometry>
        <mesh filename="../meshes/RR_thigh.STL" scale="1 1 1"/>
      </geometry>
      <material name="orange"/>
    </visual>
    <collision>
        <!-- <origin
                xyz="0 -0.13 -0.1"
                rpy="0 1.57 0" />
        <geometry>
            <box size="0.25 0.03 0.03" />
        </geometry> -->
        <origin rpy="0 0 0" xyz="0 0 0"/>
        <geometry>
          <mesh filename="../meshes/RR_thigh.STL" scale="1 1 1"/>
        </geometry>
    </collision>
    <inertial>
      <origin rpy="0 0 0" xyz="-0.010416 -0.10536 -0.097844"/>
      <mass value="2.5024"/>
      <inertia
        ixx="0.025431"
        ixy="-2.939E-06"
        ixz="0.00084298"
        iyy="0.027274"
        iyz="-0.00015729"
        izz="0.0024159" />
    </inertial>
  </link>

  <joint name="RR_calf_joint" type="revolute">
    <origin rpy="0 0 0" xyz="0 -0.1223 -0.35"/>
    <parent link="RR_thigh"/>
    <child link="RR_calf"/>
    <axis xyz="0 1 0"/>
    <dynamics damping="0.01" friction="0.2"/>
    <limit lower="-2.76634" upper="-0.68067" effort="360" velocity="12" />
  </joint>
  <link name="RR_calf">
    <visual>
      <origin rpy="0 0 0" xyz="0 0 0"/>
      <geometry>
        <mesh filename="../meshes/RR_calf.STL" scale="1 1 1"/>
      </geometry>
      <material name="orange"/>
    </visual>
    <collision>
        <!-- <origin
                xyz="0 0 -0.1"
                rpy="0 -0.18 0" />
        <geometry>
            <box size="0.02 0.03 0.2" />
        </geometry> -->
        <origin rpy="0 0 0" xyz="0 0 0"/>
        <geometry>
          <mesh filename="../meshes/RR_calf.STL" scale="1 1 1"/>
        </geometry>
    </collision>
    <inertial>
      <origin rpy="0 0 0" xyz="0.020605 2.0212E-05 -0.17304"/>
      <mass value="0.64862"/>
      <inertia
        ixx="0.0096705"
        ixy="-1.0312E-07"
        ixz="-0.00070677"
        iyy="0.0098542"
        iyz="2.2788E-06"
        izz="0.00031766" />
    </inertial>

  </link>
  <joint name="RR_foot_fixed" type="fixed">
    <origin rpy="0 0 0" xyz="0 0 -0.35"/>
    <parent link="RR_calf"/>
    <child link="RR_foot"/>
  </joint>

  <link name="RR_foot">
    <visual>
      <origin rpy="0 0 0" xyz="0 0 0"/>
      <geometry>
        <mesh filename="../meshes/RR_foot.STL" scale="1 1 1"/>
      </geometry>
      <material name="orange"/>
    </visual>
    <collision>
      <origin rpy="0 0 0" xyz="0 0 0"/>
      <geometry>
        <mesh filename="../meshes/RR_foot.STL" scale="1 1 1"/>
      </geometry>
    </collision>
    <inertial>
      <mass value="0.17599"/>
      <inertia
        ixx="0.00011036"
        ixy="7.0563E-10"
        ixz="-3.5069E-05"
        iyy="9.5157E-05"
        iyz="-7.843E-10"
        izz="0.00010548" />
    </inertial>
  </link>

  <transmission name="RR_hip_tran">
    <type>transmission_interface/SimpleTransmission</type>
    <joint name="RR_hip_joint">
      <hardwareInterface>hardware_interface/EffortJointInterface</hardwareInterface>
    </joint>
    <actuator name="RR_hip_motor">
      <hardwareInterface>hardware_interface/EffortJointInterface</hardwareInterface>
      <mechanicalReduction>1</mechanicalReduction>
    </actuator>
  </transmission>
  <transmission name="RR_thigh_tran">
    <type>transmission_interface/SimpleTransmission</type>
    <joint name="RR_thigh_joint">
      <hardwareInterface>hardware_interface/EffortJointInterface</hardwareInterface>
    </joint>
    <actuator name="RR_thigh_motor">
      <hardwareInterface>hardware_interface/EffortJointInterface</hardwareInterface>
      <mechanicalReduction>1</mechanicalReduction>
    </actuator>
  </transmission>
  <transmission name="RR_calf_tran">
    <type>transmission_interface/SimpleTransmission</type>
    <joint name="RR_calf_joint">
      <hardwareInterface>hardware_interface/EffortJointInterface</hardwareInterface>
    </joint>
    <actuator name="RR_calf_motor">
      <hardwareInterface>hardware_interface/EffortJointInterface</hardwareInterface>
      <mechanicalReduction>1</mechanicalReduction>
    </actuator>
  </transmission>

  <!-- <xacro:stairs stairs="15" xpos="0" ypos="2.0" zpos="0" /> -->
</robot>

