<mujoco model="go1_description">
    <compiler angle="radian" meshdir="../meshes/" />
    <size njmax="500" nconmax="100" />
    <option gravity='0 0 -9.806' iterations='50' solver='Newton' timestep='0.002'/>

    <default>
        <geom contype="1" conaffinity="1" friction="0.6 0.3 0.3" rgba="0.5 0.6 0.7 1" margin="0.001" group="0"/>

        <light castshadow="false" diffuse="1 1 1"/>
        <motor ctrlrange="-33.5 33.5" ctrllimited="true"/>
        <camera fovy="60"/>
        <joint damping="0.01" armature="0.01" frictionloss="0.2" />
    
    </default>

    <asset>
        <mesh name="trunk" file="trunk.stl" />
        <mesh name="hip" file="hip.stl" />
        <mesh name="thigh_mirror" file="thigh_mirror.stl" />
        <mesh name="calf" file="calf.stl" />
        <mesh name="thigh" file="thigh.stl" />
    </asset>

    <asset>
        <texture type="skybox" builtin="gradient" rgb1="1.0 1.0 1.0" rgb2="1.0 1.0 1.0" width="512" height="512"/>
        <texture name="plane" type="2d" builtin="flat" rgb1="1 1 1" rgb2="1 1 1" width="512" height="512" mark="cross" markrgb="0 0 0"/>
        <material name="plane" reflectance="0.0" texture="plane" texrepeat="3 3" texuniform="true"/>
    </asset>

    <visual>
        <rgba com="0.502 1.0 0 0.5" contactforce="0.98 0.4 0.4 0.7" contactpoint="1.0 1.0 0.6 0.4"/>
        <scale com="0.2" forcewidth="0.035" contactwidth="0.10" contactheight="0.04"/>
    </visual>

    <worldbody>
        <light directional="true" diffuse=".8 .8 .8" pos="0 0 10" dir="0 0 -10"/>
        <camera name="track" mode="trackcom" pos="0 -1.3 1.6" xyaxes="1 0 0 0 0.707 0.707"/>
        <geom name='floor' type='plane' conaffinity='1' condim='3' contype='1' rgba="0.5 0.9 0.9 0.1" material='plane' pos='0 0 0' size='0 0 1'/>

        <body name="trunk" pos="0 0 0.35">
            <inertial pos="0.0116053 0.00442221 0.000106692" quat="0.0111438 0.707126 -0.00935374 0.706938" mass="4.801" diaginertia="0.0447997 0.0366257 0.0162187" />
            <joint type="free" />
            <geom type="mesh" contype="0" conaffinity="0" group="1" rgba="0.913725 0.913725 0.847059 1" mesh="trunk" />
            <geom size="0.13 0.04675 0.057" type="box" rgba="0.913725 0.913725 0.847059 1" />
            <geom size="0.0005 0.0005 0.0005" pos="-0.01592 -0.06659 -0.00617" type="box" contype="0" conaffinity="0" group="1" rgba="0.8 0 0 0" />
            <geom size="0.0005 0.0005 0.0005" pos="-0.01592 -0.06659 -0.00617" type="box" rgba="0.8 0 0 0" />
            <site name="imu" pos="0 0 0"/>

            <body name="FL_hip" pos="0.1881 0.04675 0">
                <inertial pos="-0.00406411 0.0193463 4.50733e-06" quat="0.531662 0.467526 -0.530431 0.466259" mass="0.679292" diaginertia="0.00131334 0.00122648 0.000728484" />
                <joint name="FL_hip_joint" pos="0 0 0" axis="1 0 0" limited="true" range="-0.802851 0.802851" />
                <geom type="mesh" contype="0" conaffinity="0" group="1" rgba="0.913725 0.913725 0.847059 1" mesh="hip" />
                <geom size="0.046 0.02" pos="0 0.045 0" quat="0.707107 0.707107 0 0" type="cylinder" rgba="0.913725 0.913725 0.847059 0" />
                <geom size="0.031 0.02" pos="0 0.07 0" quat="0.707107 0.707107 0 0" type="cylinder" rgba="0.913725 0.913725 0.847059 0" />

                <body name="FL_thigh" pos="0 0.08 0">
                    <inertial pos="-0.003468 -0.018947 -0.032736" quat="0.999266 -0.00067676 -0.0382978 -0.000639813" mass="0.898919" diaginertia="0.00542178 0.00514246 0.000998869" />
                    <joint name="FL_thigh_joint" pos="0 0 0" axis="0 1 0" limited="true" range="-1.0472 4.18879" />
                    <geom type="mesh" contype="0" conaffinity="0" group="1" rgba="0.913725 0.913725 0.847059 1" mesh="thigh" />
                    <geom size="0.1065 0.01225 0.017" pos="0 0 -0.1065" quat="0.707107 0 0.707107 0" type="box" rgba="0.913725 0.913725 0.847059 0" />
                    <body name="FL_calf" pos="0 0 -0.213">
                        <inertial pos="0.00455603 0.0009473 -0.147239" quat="0.762045 0.00970173 0.0180098 0.647201" mass="0.218015" diaginertia="0.00399678 0.00398122 3.99428e-05" />
                        <joint name="FL_calf_joint" pos="0 0 0" axis="0 1 0" limited="true" range="-2.69653 -0.916298" />
                        <geom type="mesh" contype="0" conaffinity="0" group="1" rgba="0 0 0 1" mesh="calf" />
                        <geom size="0.1065 0.008 0.008" pos="0 0 -0.1065" quat="0.707107 0 0.707107 0" type="box" rgba="0.913725 0.913725 0.847059 0" />
                        <geom size="0.01" pos="0 0 -0.213" contype="0" conaffinity="0" group="1" rgba="0 0 0 1" />
                        <geom size="0.02" pos="0 0 -0.213" rgba="0 0 0 1" />
                    </body>
                </body>
            </body>

            <body name="FR_hip" pos="0.1881 -0.04675 0">
                <inertial pos="-0.00406411 -0.0193463 4.50733e-06" quat="0.467526 0.531662 -0.466259 0.530431" mass="0.679292" diaginertia="0.00131334 0.00122648 0.000728484" />
                <joint name="FR_hip_joint" pos="0 0 0" axis="1 0 0" limited="true" range="-0.802851 0.802851" />
                <geom quat="0 1 0 0" type="mesh" contype="0" conaffinity="0" group="1" rgba="0.913725 0.913725 0.847059 1" mesh="hip" />
                <geom size="0.046 0.02" pos="0 -0.045 0" quat="0.707107 0.707107 0 0" type="cylinder" rgba="0.913725 0.913725 0.847059 0" />
                <geom size="0.031 0.02" pos="0 -0.07 0" quat="0.707107 0.707107 0 0" type="cylinder" rgba="0.913725 0.913725 0.847059 0" />

                <body name="FR_thigh" pos="0 -0.08 0">
                    <inertial pos="-0.003468 0.018947 -0.032736" quat="0.999266 0.00067676 -0.0382978 0.000639813" mass="0.898919" diaginertia="0.00542178 0.00514246 0.000998869" />
                    <joint name="FR_thigh_joint" pos="0 0 0" axis="0 1 0" limited="true" range="-1.0472 4.18879" />
                    <geom type="mesh" contype="0" conaffinity="0" group="1" rgba="0.913725 0.913725 0.847059 1" mesh="thigh_mirror" />
                    <geom size="0.1065 0.01225 0.017" pos="0 0 -0.1065" quat="0.707107 0 0.707107 0" type="box" rgba="0.913725 0.913725 0.847059 0" />
                    <body name="FR_calf" pos="0 0 -0.213">
                        <inertial pos="0.00455603 0.0009473 -0.147239" quat="0.762045 0.00970173 0.0180098 0.647201" mass="0.218015" diaginertia="0.00399678 0.00398122 3.99428e-05" />
                        <joint name="FR_calf_joint" pos="0 0 0" axis="0 1 0" limited="true" range="-2.69653 -0.916298" />
                        <geom type="mesh" contype="0" conaffinity="0" group="1" rgba="0 0 0 1" mesh="calf" />
                        <geom size="0.1065 0.008 0.008" pos="0 0 -0.1065" quat="0.707107 0 0.707107 0" type="box" rgba="0 0 0 0" />
                        <geom size="0.01" pos="0 0 -0.213" contype="0" conaffinity="0" group="1" rgba="0 0 0 1" />
                        <geom size="0.02" pos="0 0 -0.213" rgba="0 0 0 1" />
                    </body>
                </body>
            </body>

            <body name="RL_hip" pos="-0.1881 0.04675 0">
                <inertial pos="0.00406411 0.0193463 4.50733e-06" quat="0.466259 0.530431 -0.467526 0.531662" mass="0.679292" diaginertia="0.00131334 0.00122648 0.000728484" />
                <joint name="RL_hip_joint" pos="0 0 0" axis="1 0 0" limited="true" range="-0.802851 0.802851"  />
                <geom quat="0 0 1 0" type="mesh" contype="0" conaffinity="0" group="1" rgba="0.913725 0.913725 0.847059 1" mesh="hip" />
                <geom size="0.046 0.02" quat="0.707107 0.707107 0 0" type="cylinder" rgba="0.913725 0.913725 0.847059 1" />
                <geom size="0.046 0.02" pos="0 0.045 0" quat="0.707107 0.707107 0 0" type="cylinder" rgba="0.913725 0.913725 0.847059 0" />
                <geom size="0.031 0.02" pos="0 0.07 0" quat="0.707107 0.707107 0 0" type="cylinder" rgba="0.913725 0.913725 0.847059 0" />

                <body name="RL_thigh" pos="0 0.08 0">
                    <inertial pos="-0.003468 -0.018947 -0.032736" quat="0.999266 -0.00067676 -0.0382978 -0.000639813" mass="0.898919" diaginertia="0.00542178 0.00514246 0.000998869" />
                    <joint name="RL_thigh_joint" pos="0 0 0" axis="0 1 0" limited="true" range="-1.0472 4.18879" />
                    <geom type="mesh" contype="0" conaffinity="0" group="1" rgba="0.913725 0.913725 0.847059 1" mesh="thigh" />
                    <geom size="0.1065 0.01225 0.017" pos="0 0 -0.1065" quat="0.707107 0 0.707107 0" type="box" rgba="0.913725 0.913725 0.847059 0" />
                    <body name="RL_calf" pos="0 0 -0.213">
                        <inertial pos="0.00455603 0.0009473 -0.147239" quat="0.762045 0.00970173 0.0180098 0.647201" mass="0.218015" diaginertia="0.00399678 0.00398122 3.99428e-05" />
                        <joint name="RL_calf_joint" pos="0 0 0" axis="0 1 0" limited="true" range="-2.69653 -0.916298" />
                        <geom type="mesh" contype="0" conaffinity="0" group="1" rgba="0 0 0 1" mesh="calf" />
                        <geom size="0.1065 0.008 0.008" pos="0 0 -0.1065" quat="0.707107 0 0.707107 0" type="box" rgba="0 0 0 0" />
                        <geom size="0.01" pos="0 0 -0.213" contype="0" conaffinity="0" group="1" rgba="0 0 0 1" />
                        <geom size="0.02" pos="0 0 -0.213" rgba="0 0 0 1" />
                    </body>
                </body>
            </body>

            <body name="RR_hip" pos="-0.1881 -0.04675 0">
                <inertial pos="0.00406411 -0.0193463 4.50733e-06" quat="0.530431 0.466259 -0.531662 0.467526" mass="0.679292" diaginertia="0.00131334 0.00122648 0.000728484" />
                <joint name="RR_hip_joint" pos="0 0 0" axis="1 0 0" limited="true" range="-0.802851 0.802851" />
                <geom quat="0 0 0 -1" type="mesh" contype="0" conaffinity="0" group="1" rgba="0.913725 0.913725 0.847059 1" mesh="hip" />
                <geom size="0.046 0.02" quat="0.707107 0.707107 0 0" type="cylinder" rgba="0.913725 0.913725 0.847059 1" />
                <geom size="0.046 0.02" pos="0 -0.045 0" quat="0.707107 0.707107 0 0" type="cylinder" rgba="0.913725 0.913725 0.847059 0" />
                <geom size="0.031 0.02" pos="0 -0.07 0" quat="0.707107 0.707107 0 0" type="cylinder" rgba="0.913725 0.913725 0.847059 0" />
        
                <body name="RR_thigh" pos="0 -0.08 0">
                    <inertial pos="-0.003468 0.018947 -0.032736" quat="0.999266 0.00067676 -0.0382978 0.000639813" mass="0.898919" diaginertia="0.00542178 0.00514246 0.000998869" />
                    <joint name="RR_thigh_joint" pos="0 0 0" axis="0 1 0" limited="true" range="-1.0472 4.18879" />
                    <geom type="mesh" contype="0" conaffinity="0" group="1" rgba="0.913725 0.913725 0.847059 1" mesh="thigh_mirror" />
                    <geom size="0.1065 0.01225 0.017" pos="0 0 -0.1065" quat="0.707107 0 0.707107 0" type="box" rgba="0.913725 0.913725 0.847059 0" />
                    <body name="RR_calf" pos="0 0 -0.213">
                        <inertial pos="0.00455603 0.0009473 -0.147239" quat="0.762045 0.00970173 0.0180098 0.647201" mass="0.218015" diaginertia="0.00399678 0.00398122 3.99428e-05" />
                        <joint name="RR_calf_joint" pos="0 0 0" axis="0 1 0" limited="true" range="-2.69653 -0.916298" />
                        <geom type="mesh" contype="0" conaffinity="0" group="1" rgba="0 0 0 1" mesh="calf" />
                        <geom size="0.1065 0.008 0.008" pos="0 0 -0.1065" quat="0.707107 0 0.707107 0" type="box" rgba="0 0 0 0" />
                        <geom size="0.01" pos="0 0 -0.213" contype="0" conaffinity="0" group="1" rgba="0 0 0 1" />
                        <geom size="0.02" pos="0 0 -0.213" rgba="0 0 0 1" />
                    </body>
                </body>
            </body>
        </body>
    </worldbody>

 	<actuator>      
		<motor name="FL_hip_joint" joint="FL_hip_joint" gear="1"/>
		<motor name="FL_thigh_joint" joint="FL_thigh_joint" gear="1"/>
		<motor name="FL_calf_joint" joint="FL_calf_joint" gear="1"/>

		<motor name="FR_hip_joint" joint="FR_hip_joint" gear="1"/>
		<motor name="FR_thigh_joint" joint="FR_thigh_joint" gear="1"/>
		<motor name="FR_calf_joint" joint="FR_calf_joint" gear="1"/>

		<motor name="RL_hip_joint" joint="RL_hip_joint" gear="1"/>
		<motor name="RL_thigh_joint" joint="RL_thigh_joint" gear="1"/>
		<motor name="RL_calf_joint" joint="RL_calf_joint" gear="1"/>

		<motor name="RR_hip_joint" joint="RR_hip_joint" gear="1"/>
		<motor name="RR_thigh_joint" joint="RR_thigh_joint" gear="1"/>
		<motor name="RR_calf_joint" joint="RR_calf_joint" gear="1"/>
    </actuator>

    <sensor>
        <actuatorpos name='FL_hip_joint_p'  actuator='FL_hip_joint' user='13'/>
		<actuatorpos name='FL_thigh_joint_p'  actuator='FL_thigh_joint' user='13'/>
		<actuatorpos name='FL_calf_joint_p'  actuator='FL_calf_joint' user='13'/>

		<actuatorpos name='FR_hip_joint_p'  actuator='FR_hip_joint' user='13'/>
		<actuatorpos name='FR_thigh_joint_p'  actuator='FR_thigh_joint' user='13'/>
		<actuatorpos name='FR_calf_joint_p'  actuator='FR_calf_joint' user='13'/>

		<actuatorpos name='RL_hip_joint_p'  actuator='RL_hip_joint' user='13'/>
		<actuatorpos name='RL_thigh_joint_p'  actuator='RL_thigh_joint' user='13'/>
		<actuatorpos name='RL_calf_joint_p'  actuator='RL_calf_joint' user='13'/>

		<actuatorpos name='RR_hip_joint_p'  actuator='RR_hip_joint' user='13'/>
		<actuatorpos name='RR_thigh_joint_p'  actuator='RR_thigh_joint' user='13'/>
		<actuatorpos name='RR_calf_joint_p'  actuator='RR_calf_joint' user='13'/>

        <actuatorvel name='FL_hip_joint_v'  actuator='FL_hip_joint' user='13'/>
        <actuatorvel name='FL_thigh_joint_v'  actuator='FL_thigh_joint' user='13'/>
        <actuatorvel name='FL_calf_joint_v'  actuator='FL_calf_joint' user='13'/>

        <actuatorvel name='FR_hip_joint_v'  actuator='FR_hip_joint' user='13'/>
        <actuatorvel name='FR_thigh_joint_v'  actuator='FR_thigh_joint' user='13'/>
        <actuatorvel name='FR_calf_joint_v'  actuator='FR_calf_joint' user='13'/>

        <actuatorvel name='RL_hip_joint_v'  actuator='RL_hip_joint' user='13'/>
        <actuatorvel name='RL_thigh_joint_v'  actuator='RL_thigh_joint' user='13'/>
        <actuatorvel name='RL_calf_joint_v'  actuator='RL_calf_joint' user='13'/>
        
        <actuatorvel name='RR_hip_joint_v'  actuator='RR_hip_joint' user='13'/>
        <actuatorvel name='RR_thigh_joint_v'  actuator='RR_thigh_joint' user='13'/>
        <actuatorvel name='RR_calf_joint_v'  actuator='RR_calf_joint' user='13'/>

		<actuatorfrc name='FL_hip_joint_f'  actuator='FL_hip_joint'  user='13' noise='1e-3'/>
		<actuatorfrc name='FL_thigh_joint_f'  actuator='FL_thigh_joint'  user='13' noise='1e-3'/>
		<actuatorfrc name='FL_calf_joint_f'  actuator='FL_calf_joint'  user='13' noise='1e-3'/>

		<actuatorfrc name='FR_hip_joint_f'  actuator='FR_hip_joint'  user='13' noise='1e-3'/>
		<actuatorfrc name='FR_thigh_joint_f'  actuator='FR_thigh_joint'  user='13' noise='1e-3'/>
		<actuatorfrc name='FR_calf_joint_f'  actuator='FR_calf_joint'  user='13' noise='1e-3'/>
		
		<actuatorfrc name='RL_hip_joint_f'  actuator='RL_hip_joint'  user='13' noise='1e-3'/>
		<actuatorfrc name='RL_thigh_joint_f'  actuator='RL_thigh_joint'  user='13' noise='1e-3'/>
		<actuatorfrc name='RL_calf_joint_f'  actuator='RL_calf_joint'  user='13' noise='1e-3'/>

        <actuatorfrc name='RR_hip_joint_f'  actuator='RR_hip_joint'  user='13' noise='1e-3'/>
		<actuatorfrc name='RR_thigh_joint_f'  actuator='RR_thigh_joint'  user='13' noise='1e-3'/>
		<actuatorfrc name='RR_calf_joint_f'  actuator='RR_calf_joint'  user='13' noise='1e-3'/>

        <!-- <framequat     name='orientation' objtype='site' noise='0.001' objname='imu'/>
        <framepos      name='position' objtype='site' noise='0.001' objname='imu'/>
        <gyro          name='angular-velocity'    site='imu' noise='0.005' cutoff='34.9'/>
        <velocimeter   name='linear-velocity'     site='imu' noise='0.001' cutoff='30'/>
        <accelerometer name='linear-acceleration' site='imu' noise='0.005' cutoff='157'/>
        <magnetometer  name='magnetometer'        site='imu'/> -->

        <framequat     name='orientation' objtype='site' noise='0.001' objname='imu'/>
        <framepos      name='position' objtype='site' noise='0.001' objname='imu'/>
        <gyro          name='angular-velocity'    site='imu' noise='0.005'/>
        <velocimeter   name='linear-velocity'     site='imu' noise='0.001'/>
        <accelerometer name='linear-acceleration' site='imu' noise='0.005'/>
        <magnetometer  name='magnetometer'        site='imu'/>
    
    </sensor>
</mujoco>
